<?xml version="1.0" ?>
<robot name="agribot_v2" xmlns:xacro="http://www.ros.org/wiki/xacro">

<xacro:include filename="$(find agribot_v2_description)/urdf/materials.xacro" />
<xacro:include filename="$(find agribot_v2_description)/urdf/agribot_v2.trans" />
<xacro:include filename="$(find agribot_v2_description)/urdf/agribot_v2.gazebo" />

<link name="base_link">
   <inertial>
    <origin rpy="0 0 0" xyz="1.0414918880029151e-13 -0.010521181260593255 0.5886619317061533"/>
    <mass value="20"/>
    <inertia ixx="5.642923" ixy="0.0" ixz="0.0" iyy="3.97925" iyz="0.0" izz="7.005167"/>
  </inertial>
  <visual>
    <origin rpy="0 0 0" xyz="0 0 0"/>
    <geometry>
      <mesh filename="package://agribot_v2_description/meshes/base_link.stl" scale="0.001 0.001 0.001"/>
    </geometry>
    <material name="silver"/>
  </visual>
  <collision>
    <origin rpy="0 0 0" xyz="0 0 0"/>
    <geometry>
      <mesh filename="package://agribot_v2_description/meshes/base_link.stl" scale="0.001 0.001 0.001"/>
    </geometry>
  </collision>
</link>

<link name="front_camera_1">
  <inertial>
    <origin rpy="0 0 0" xyz="6.661338147750939e-16 -0.010000000000031983 -1.5987211554602254e-14"/>
    <mass value="0.6279999999999999"/>
    <inertia ixx="0.000105" ixy="0.0" ixz="-0.0" iyy="0.000607" iyz="0.0" izz="0.000544"/>
  </inertial>
  <visual>
    <origin rpy="0 0 0" xyz="-0.0 0.55 -0.909"/>
    <geometry>
      <mesh filename="package://agribot_v2_description/meshes/front_camera_1.stl" scale="0.001 0.001 0.001"/>
    </geometry>
    <material name="silver"/>
  </visual>
  <collision>
    <origin rpy="0 0 0" xyz="-0.0 0.55 -0.909"/>
    <geometry>
      <mesh filename="package://agribot_v2_description/meshes/front_camera_1.stl" scale="0.001 0.001 0.001"/>
    </geometry>
  </collision>
</link>

<link name="wheel_front_right_1">
  <inertial>
    <origin rpy="0 0 0" xyz="1.6653345369377348e-15 -2.55351295663786e-15 -2.42861286636753e-14"/>
    <mass value="1.6289478529389372"/>
    <inertia ixx="0.00963" ixy="-0.0" ixz="0.0" iyy="0.005141" iyz="-0.0" izz="0.005141"/>
  </inertial>
  <visual>
    <origin rpy="0 0 0" xyz="0.4 0.53 -0.1"/>
    <geometry>
      <mesh filename="package://agribot_v2_description/meshes/wheel_front_right_1.stl" scale="0.001 0.001 0.001"/>
    </geometry>
    <material name="silver"/>
  </visual>
  <collision>
    <origin rpy="0 0 0" xyz="0.4 0.53 -0.1"/>
    <geometry>
      <mesh filename="package://agribot_v2_description/meshes/wheel_front_right_1.stl" scale="0.001 0.001 0.001"/>
    </geometry>
  </collision>
</link>

<link name="wheel_front_left_1">
  <inertial>
    <origin rpy="0 0 0" xyz="0.0 -2.1094237467877974e-15 8.604228440844963e-15"/>
    <mass value="1.6289478529389372"/>
    <inertia ixx="0.00963" ixy="0.0" ixz="0.0" iyy="0.005141" iyz="0.0" izz="0.005141"/>
  </inertial>
  <visual>
    <origin rpy="0 0 0" xyz="-0.4 0.53 -0.1"/>
    <geometry>
      <mesh filename="package://agribot_v2_description/meshes/wheel_front_left_1.stl" scale="0.001 0.001 0.001"/>
    </geometry>
    <material name="silver"/>
  </visual>
  <collision>
    <origin rpy="0 0 0" xyz="-0.4 0.53 -0.1"/>
    <geometry>
      <mesh filename="package://agribot_v2_description/meshes/wheel_front_left_1.stl" scale="0.001 0.001 0.001"/>
    </geometry>
  </collision>
</link>

<link name="wheel_back_left_1">
  <inertial>
    <origin rpy="0 0 0" xyz="1.709743457922741e-14 -4.107825191113079e-15 4.621303340002214e-14"/>
    <mass value="1.6289478529389372"/>
    <inertia ixx="0.00963" ixy="-0.0" ixz="-0.0" iyy="0.005141" iyz="0.0" izz="0.005141"/>
  </inertial>
  <visual>
    <origin rpy="0 0 0" xyz="-0.4 -0.53 -0.1"/>
    <geometry>
      <mesh filename="package://agribot_v2_description/meshes/wheel_back_left_1.stl" scale="0.001 0.001 0.001"/>
    </geometry>
    <material name="silver"/>
  </visual>
  <collision>
    <origin rpy="0 0 0" xyz="-0.4 -0.53 -0.1"/>
    <geometry>
      <mesh filename="package://agribot_v2_description/meshes/wheel_back_left_1.stl" scale="0.001 0.001 0.001"/>
    </geometry>
  </collision>
</link>

<link name="wheel_back_right_1">
  <inertial>
    <origin rpy="0 0 0" xyz="-1.532107773982716e-14 -4.107825191113079e-15 1.326716514427062e-14"/>
    <mass value="1.6289478529389372"/>
    <inertia ixx="0.00963" ixy="0.0" ixz="0.0" iyy="0.005141" iyz="-0.0" izz="0.005141"/>
  </inertial>
  <visual>
    <origin rpy="0 0 0" xyz="0.4 -0.53 -0.1"/>
    <geometry>
      <mesh filename="package://agribot_v2_description/meshes/wheel_back_right_1.stl" scale="0.001 0.001 0.001"/>
    </geometry>
    <material name="silver"/>
  </visual>
  <collision>
    <origin rpy="0 0 0" xyz="0.4 -0.53 -0.1"/>
    <geometry>
      <mesh filename="package://agribot_v2_description/meshes/wheel_back_right_1.stl" scale="0.001 0.001 0.001"/>
    </geometry>
  </collision>
</link>

<link name="seeder_3">
  <inertial>
    <origin rpy="0 0 0" xyz="-1.43496455451624e-14 0.0004999999999656946 -0.5144321737427789"/>
    <mass value="1.278010008270655"/>
    <inertia ixx="0.287544" ixy="0.0" ixz="-0.0" iyy="0.287544" iyz="0.0" izz="0.002269"/>
  </inertial>
  <visual>
    <origin rpy="0 0 0" xyz="-0.0 0.351 -1.015275"/>
    <geometry>
      <mesh filename="package://agribot_v2_description/meshes/seeder_3.stl" scale="0.001 0.001 0.001"/>
    </geometry>
    <material name="silver"/>
  </visual>
  <!-- <collision>
    <origin rpy="0 0 0" xyz="-0.0 0.351 -1.015275"/>
    <geometry>
      <mesh filename="package://agribot_v2_description/meshes/seeder_3.stl" scale="0.001 0.001 0.001"/>
    </geometry>
  </collision> -->
</link>

<link name="sprayer_v12_1">
  <inertial>
    <origin rpy="0 0 0" xyz="-0.004947326062087478 0.037246464695549736 0.10092673884236347"/>
    <mass value="3.151407529550895"/>
    <inertia ixx="2.433335" ixy="-0.011637" ixz="0.045914" iyy="2.175931" iyz="0.109854" izz="4.122608"/>
  </inertial>
  <visual>
    <origin rpy="0 0 0" xyz="-0.0 0.0 -0.745275"/>
    <geometry>
      <mesh filename="package://agribot_v2_description/meshes/sprayer_v12_1.stl" scale="0.001 0.001 0.001"/>
    </geometry>
    <material name="silver"/>
  </visual>
  <collision>
    <origin rpy="0 0 0" xyz="-0.0 0.0 -0.745275"/>
    <geometry>
      <mesh filename="package://agribot_v2_description/meshes/sprayer_v12_1.stl" scale="0.001 0.001 0.001"/>
    </geometry>
  </collision>
</link>

<joint name="Rigid14" type="fixed">
  <!-- <origin rpy="0 0 0" xyz="0.0 -0.55 0.909"/> -->
  <origin rpy="0 1.0 -1.57" xyz="0.0 -0.5495 0.909"/>
  <parent link="base_link"/>
  <child link="front_camera_1"/>
</joint>

<joint name="wheel_front_right_joint" type="continuous">
  <origin rpy="0 0 0" xyz="-0.4 -0.53 0.1"/>
  <parent link="base_link"/>
  <child link="wheel_front_right_1"/>
  <axis xyz="1.0 -0.0 -0.0"/>
</joint>

<joint name="wheel_front_left_joint" type="continuous">
  <origin rpy="0 0 0" xyz="0.4 -0.53 0.1"/>
  <parent link="base_link"/>
  <child link="wheel_front_left_1"/>
  <axis xyz="1.0 0.0 -0.0"/>
</joint>

<joint name="wheel_back_left_joint" type="continuous">
  <origin rpy="0 0 0" xyz="0.4 0.53 0.1"/>
  <parent link="base_link"/>
  <child link="wheel_back_left_1"/>
  <axis xyz="1.0 0.0 -0.0"/>
</joint>

<joint name="wheel_back_right_joint" type="continuous">
  <origin rpy="0 0 0" xyz="-0.4 0.53 0.1"/>
  <parent link="base_link"/>
  <child link="wheel_back_right_1"/>
  <axis xyz="1.0 -0.0 -0.0"/>
</joint>

<joint name="seeder_joint" type="prismatic">
  <origin rpy="0 0 0" xyz="0.0 -0.351 1.015275"/>
  <parent link="base_link"/>
  <child link="seeder_3"/>
  <axis xyz="0.0 -0.0 1.0"/>
  <limit effort="100" lower="-0.25" upper="-0.01" velocity="100"/>
</joint>

<joint name="Rigid31" type="fixed">
  <origin rpy="0 0 0" xyz="0.0 0.0 0.745275"/>
  <parent link="base_link"/>
  <child link="sprayer_v12_1"/>
</joint>

</robot>
